Workbook

Sheet Budgets 2627
B3: French league (Betclic Elite)
B4: Nation | C4: Club | D4: Total Budget | E4: Gross salary budget | F4: Salary % from total budget | G4: Budget increase from the last season | H4: Place in the national league after the regular season | I4: Participation in European tournament
B5: France | C5: Paris | F5: =+E5/D5 -> #DIV/0! | H5: - | I5: -
B6: France | C6: Monaco | F6: =+E6/D6 -> #DIV/0! | H6: - | I6: -
B7: France | C7: Nanterre | F7: =+E7/D7 -> #DIV/0! | H7: - | I7: -
B8: France | C8: Asvel | F8: =+E8/D8 -> #DIV/0! | H8: - | I8: -
B9: France | C9: Cholet | F9: =+E9/D9 -> #DIV/0! | H9: - | I9: -
B10: France | C10: Le Mans | F10: =+E10/D10 -> #DIV/0! | H10: - | I10: -
B11: France | C11: Bourg-en-Bresse | F11: =+E11/D11 -> #DIV/0! | H11: - | I11: -
B12: France | C12: Strasbourg | F12: =+E12/D12 -> #DIV/0! | H12: - | I12: -
B13: France | C13: Chalon | F13: =+E13/D13 -> #DIV/0! | H13: - | I13: -
B14: France | C14: Nancy | F14: =+E14/D14 -> #DIV/0! | H14: - | I14: -
B15: France | C15: Dijon | F15: =+E15/D15 -> #DIV/0! | H15: - | I15: -
B16: France | C16: Boulazac | F16: =+E16/D16 -> #DIV/0! | H16: - | I16: -
... B20: France | C20: Le Portel | F20: =+E20/D20 -> #DIV/0! | H20: - | I20: -
E21: League average | F21: =average(F5:F20) -> #DIV/0!
B23: German league (easyCredit BBL)
B24: Nation | C24: Club | D24: Total Budget | E24: Gross salary budget | F24: Salary % from total budget | G24: Budget increase from the last season | H24: Place in the national league after the regular season | I24: Participation in European tournament
B25: Germany | C25: FC Bayern | F25: =+E25/D25 -> #DIV/0! | H25: - | I25: -
B26: Germany | C26: Alba Berlin | F26: =+E26/D26 -> #DIV/0! | H26: - | I26: -
B27: Germany | C27: Bamberg Baskets | F27: =+E27/D27 -> #DIV/0! | H27: - | I27: -
B28: Germany | C28: Telekom Baskets Bonn | F28: =+E28/D28 -> #DIV/0! | H28: - | I28: -
B29: Germany | C29: Wurzburg | F29: =+E29/D29 -> #DIV/0! | H29: - | I29: -
B30: Germany | C30: Ratiopharm Ulm | F30: =+E30/D30 -> #DIV/0! | H30: - | I30: -
B31: Germany | C31: Rasta Vechta | F31: =+E31/D31 -> #DIV/0! | H31: - | I31: -
B32: Germany | C32: Gladiators Trier | F32: =+E32/D32 -> #DIV/0! | H32: - | I32: -
B33: Germany | C33: Rostock Seawolves | F33: =+E33/D33 -> #DIV/0! | H33: - | I33: -
B34: Germany | C34: MHP Riesen Ludwigsburg | F34: =+E34/D34 -> #DIV/0! | H34: - | I34: -
B35: Germany | C35: EWE Baskets Oldenburg | F35: =+E35/D35 -> #DIV/0! | H35: - | I35: -
B36: Germany | C36: Niners Chemnitz | F36: =+E36/D36 -> #DIV/0! | H36: - | I36: -
... B42: Germany | C42: MLP Academics Heidelberg | F42: =+E42/D42 -> #DIV/0! | H42: - | I42: -
E43: League average | F43: =average(F25:F42) -> #DIV/0!
B45: Spanish league (liga Endesa)
B46: Nation | C46: Club | D46: Total Budget | E46: Gross salary budget | F46: Salary % from total budget | G46: Budget increase from the last season | H46: Place in the national league after the regular season | I46: Participation in European tournament | J46: Source 1 | K46: Source 2 | L46: Source 3
A47: + | B47: Spain | C47: Real Madrid | D47: 55000000 | E47: 40000000 | F47: =+E47/D47 -> 0.72727273 | G47: =(D47-'Budgets 2526'!D47)/'Budgets 2526'!D47 -> 0 | H47: - | I47: - | J47: https://cronicavasca.elespanol.com/deportes/20260910/baskonia-contara-cuarto-presupuesto-acb-millones-euros/1003742791603_0.html
A48: + | B48: Spain | C48: Valencia basket | D48: 38000000 | E48: 20000000 | F48: =+E48/D48 -> 0.52631579 | G48: =(D48-'Budgets 2526'!D48)/'Budgets 2526'!D48 -> 0.085714286 | H48: - | I48: - | J48: https://www.diariosur.es/unicaja/competencia-nunca-unicaja-20260628120526-nt.html#vca=fixed-btn&vso=rrss&vmc=tw&vli=unicaja | K48: https://www.merchanendirecto.es/presupuesto-de-record-para-unicaja/ | L48: https://cronicavasca.elespanol.com/deportes/20260910/baskonia-contara-cuarto-presupuesto-acb-millones-euros/1003742791603_0.html
B49: Spain | C49: Kosner Baskonia | D49: 23000000 | E49: 15000000 | F49: =+E49/D49 -> 0.65217391 | G49: =(D49-'Budgets 2526'!D49)/'Budgets 2526'!D49 -> 0.35294118 | H49: - | I49: - | J49: https://www.merchanendirecto.es/presupuesto-de-record-para-unicaja/ | K49: https://cronicavasca.elespanol.com/deportes/20260910/baskonia-contara-cuarto-presupuesto-acb-millones-euros/1003742791603_0.html
B50: Spain | C50: UCAM Murcia | F50: =+E50/D50 -> #DIV/0! | G50: =(D50-'Budgets 2526'!D50)/'Budgets 2526'!D50 -> -1 | H50: - | I50: -
B51: Spain | C51: Barcelona | D51: 43000000 | E51: 35000000 | F51: =+E51/D51 -> 0.81395349 | G51: =(D51-'Budgets 2526'!D51)/'Budgets 2526'!D51 -> 0.069651741 | H51: - | I51: - | J51: https://www.lesportiudecatalunya.cat/basquet/article/2659368-aposta-forta-6-5-milions-d-euros-mes.html | K51: https://cronicaglobal.elespanol.com/culemania/palco/20260321/laporta-subira-presupuesto-barca-basket-millones-temporada/1003742743992_0.html | L51: https://www.sport.es/es/noticias/barca/baloncesto/salto-dara-barca-basket-nivel-130299412
B52: Spain | C52: Joventut Badalona | F52: =+E52/D52 -> #DIV/0! | G52: =(D52-'Budgets 2526'!D52)/'Budgets 2526'!D52 -> -1 | H52: - | I52: -
...

Sheet Budgets 2526
B3: French league (Betclic Elite)
B4: Nation | C4: Club | D4: Total Budget | E4: Gross salary budget | F4: Salary % from total budget | G4: Place in the national league after the regular season | H4: Participation in European tournament
B5: France | C5: Paris | D5: 28883000 | E5: 7970000 | F5: =+E5/D5 -> 0.27594086 | G5: 1 | H5: Euroleague - regular season 16 place
B6: France | C6: Monaco | D6: 38715000 | E6: 20134000 | F6: =+E6/D6 -> 0.52005683 | G6: 2 | H6: Euroleague - Top 8 / quarter-finals
B7: France | C7: Nanterre | D7: 5627000 | E7: 1598000 | F7: =+E7/D7 -> 0.28398792 | G7: 3 | H7: -
B8: France | C8: Asvel | D8: 18689000 | E8: 4546000 | F8: =+E8/D8 -> 0.24324469 | G8: 4 | H8: Euroleague - regular season 20 place
B9: France | C9: Cholet | D9: 6460000 | E9: 1631000 | F9: =+E9/D9 -> 0.25247678 | G9: 5 | H9: BCL - Play-in round
B10: France | C10: Le Mans | D10: 7510000 | E10: 2282000 | F10: =+E10/D10 -> 0.30386152 | G10: 6 | H10: BCL - Top 16 round
B11: France | C11: Bourg-en-Bresse | D11: 8122000 | E11: 2300000 | F11: =+E11/D11 -> 0.28318148 | G11: 7 | H11: Eurocup - Winners
B12: France | C12: Strasbourg | D12: 7071000 | E12: 2898000 | F12: =+E12/D12 -> 0.40984302 | G12: 8 | H12: -
B13: France | C13: Chalon | D13: 7188000 | E13: 2034000 | F13: =+E13/D13 -> 0.28297162 | G13: 9 | H13: BCL - Top 16 round
B14: France | C14: Nancy | D14: 5836000 | E14: 1733000 | F14: =+E14/D14 -> 0.29694997 | G14: 10 | H14: -
B15: France | C15: Dijon | D15: 6370000 | E15: 1965000 | F15: =+E15/D15 -> 0.30847724 | G15: 11 | H15: Fiba Europe Cup - did not advance from the group to the next round
B16: France | C16: Boulazac | D16: 3853000 | E16: 1242000 | F16: =+E16/D16 -> 0.32234622 | G16: 12 | H16: -
... B20: France | C20: Le Portel | D20: 3741000 | E20: 968000 | F20: =+E20/D20 -> 0.25875434 | G20: 16 | H20: -
E21: League average | F21: =average(F5:F20) -> 0.31542792
B23: German league (easyCredit BBL)
B24: Nation | C24: Club | D24: Total Budget | E24: Gross salary budget | F24: Salary % from total budget | G24: Place in the national league after the regular season | H24: Participation in European tournament
B25: Germany | C25: FC Bayern | D25: 48420000 | E25: 18030000 | F25: =+E25/D25 -> 0.37236679 | G25: 1 | H25: Euroleague - regular season 13 place
B26: Germany | C26: Alba Berlin | D26: 11420000 | E26: 4690000 | F26: =+E26/D26 -> 0.41068301 | G26: 2 | H26: BCL- Top 8 / quarter-finals
B27: Germany | C27: Bamberg Baskets | D27: 5580000 | E27: 1460000 | F27: =+E27/D27 -> 0.26164875 | G27: 3 | H27: -
B28: Germany | C28: Telekom Baskets Bonn | D28: 9160000 | E28: 3240000 | F28: =+E28/D28 -> 0.35371179 | G28: 4 | H28: -
B29: Germany | C29: Wurzburg | D29: 6730000 | E29: 2750000 | F29: =+E29/D29 -> 0.40861813 | G29: 5 | H29: BCL - Top 16
B30: Germany | C30: Ratiopharm Ulm | D30: 9210000 | E30: 3000000 | F30: =+E30/D30 -> 0.3257329 | G30: 6 | H30: Eurocup - regular season 7 place
B31: Germany | C31: Rasta Vechta | D31: 5680000 | E31: 2460000 | F31: =+E31/D31 -> 0.43309859 | G31: 7 | H31: Fiba Europe Cup - did not advance from the group to the next round
B32: Germany | C32: Gladiators Trier | D32: 4620000 | E32: 1560000 | F32: =+E32/D32 -> 0.33766234 | G32: 8 | H32: -
B33: Germany | C33: Rostock Seawolves | D33: 7040000 | E33: 2110000 | F33: =+E33/D33 -> 0.29971591 | G33: 9 | H33: Fiba Europe Cup - Top 16
B34: Germany | C34: MHP Riesen Ludwigsburg | D34: 5740000 | E34: 2520000 | F34: =+E34/D34 -> 0.43902439 | G34: 10 | H34: -
B35: Germany | C35: EWE Baskets Oldenburg | D35: 9080000 | E35: 3170000 | F35: =+E35/D35 -> 0.34911894 | G35: 11 | H35: -
B36: Germany | C36: Niners Chemnitz | D36: 7510000 | E36: 2760000 | F36: =+E36/D36 -> 0.36750999 | G36: 12 | H36: Eurocup - 1/8 finals
... B41: Germany | C41: Lowen Braunschweig | D41: 6680000 | E41: 1860000 | F41: =+E41/D41 -> 0.27844311 | G41: 17 | H41: Fiba Europe Cup - did not advance from the group to the next round
B42: Germany | C42: MLP Academics Heidelberg | D42: 6020000 | E42: 2200000 | F42: =+E42/D42 -> 0.3654485 | G42: 18 | H42: BCL - Play-in round | P42: Unicaja - šiek tiek virš 16 mln bendras (algoms ~9-10), (penktas didžiausias ACB, prezidento žodžiai) Tenerifė - 11-12 mln. (algoms apie 6-6.5 mln) AEK- 6-7 mln (algoms 3.5-4.5 mln) Kitos komandos TOP 8: Joventut ~9 mln (Algoms apie ~6 mln) Galatasaray - 7.7 eur (5.3 mln algoms) oficialūs skaičiai Alba Berlin - 11.4 mln (4.7 mln algoms) Nymburk - ~3 mln eur (1,5-2 mln algoms) Kitos komandos TOP16: Würzburg - 6.73 mln (algoms 2.8mln. ) Gran Canaria - ~11 mln (algoms 5-5.5 mln.) Le Mans - 7.5 mln (algoms 2.3 mln) Chalon - 7.2 mln (algoms 2 mln.) Trieste - 6-7.5 mln (algoms 3,5-4,5 mln) Tofaš - 6-8 mln. (algoms 4-5.5 mln) Holon - 4.5-6 mln (algoms 3-4 mln) Karditsas- 2.5-4 mln (algoms 1.5-2.5 mln) Rytas -6.6 mln (algoms 3.2 mln)
E43: League average | F43: =average(F25:F42) -> 0.35279557
B45: Spanish league (liga Endesa)
B46: Nation | C46: Club | D46: Total Budget | E46: Gross salary budget | F46: Salary % from total budget | G46: Place in the national league after the regular season | H46: Participation in European tournament | I46: Source 1 | J46: Source 2 | K46: Source 3
A47: + | B47: Spain | C47: Real Madrid | D47: 55000000 | E47: 34300000 | F47: =+E47/D47 -> 0.62363636 | G47: 1 | H47: Euroleague - F4 / second place | I47: https://www.2playbook.com/clubes/real-madrid-perdera-38-millones-con-baloncesto-en-2025-2026-como-paso-previo-su-apuesta-nba_20577_102.html | J47: https://encestando.es/el-real-madrid-facturo-25-millones-la-pasada-temporada-y-perdio-195-este-ano-preve-38 | K47: https://cronicaglobal.elespanol.com/culemania/palco/20251115/barca-basket-millones-real-madrid-jugadores-laporta/1003742707818_0.html
A48: + | B48: Spain | C48: Valencia | D48: 35000000 | E48: 19000000 | F48: =+E48/D48 -> 0.54285714 | G48: 2 | H48: Euroleague - F4 / semi-finals | I48: https://as.com/baloncesto/el-bilbao-basket-empieza-a-crecer-f202512-n/ | J48: https://www.basketeurope.com/euroleague-valence-booste-son-budget-a-35-millions-deuros/ | K48: https://www.lasprovincias.es/deportes/valencia-bc/valencia-basket-aprueba-presupuesto-record-millones-temporada-20251211191149-nt.html
B49: Spain | C49: Baskonia | D49: 17000000 | E49: 12000000 | F49: =+E49/D49 -> 0.70588235 | G49: 3 | H49: Euroleague - regular season 18 place | I49: https://cronicavasca.elespanol.com/deportes/20250727/baskonia-seguira-potente-acb-contara-millones-presupuesto/1003742675823_0.html | J49: https://www.elcorreo.com/baskonia/baskonia-pablo-laso-costo-113-millones-euros-20251130000753-nt.html | K49: https://cronicavasca.elespanol.com/deportes/20260227/baskonia-cuarto-presupuesto-salarial-euroliga-millones-euros/1003742736078_0.html
B50: Spain | C50: UCAM Murcia | D50: 6000000 | E50: 3900000 | F50: =+E50/D50 -> 0.65 | G50: 4 | H50: Fiba Europe Cup - F4 / semi-finals | I50: https://www.marca.com/baloncesto/acb/playoffs/2024/06/06/665de632268e3e39178b4602.html | J50: https://cadenaser.com/murcia/2025/05/14/alejandro-gomez-presupuesto-de-ucam-murcia-y-planificacion-de-la-proxima-temporada-radio-murcia/ | K50: https://palco23.mundodeportivo.com/clubes/ucam-murcia-refuerza-su-estructura-con-una-ampliacion-de-capital-de-970000-euros
B51: Spain | C51: Barcelona | D51: 40200000 | E51: 29250000 | F51: =+E51/D51 -> 0.72761194 | G51: 5 | H51: Euroleague - play-in round | I51: https://www.eurohoops.net/en/euroleague/1941681/joan-laporta-talks-budget-barcelona-euroleague/ | J51: -
...

Sheet World 2526
B3: World
B4: Nation | C4: Club | D4: Total Budget | E4: Gross salary budget | F4: Salary % from total budget | G4: Place in the national league after the regular season | H4: Participation in European tournament
B5: Latvia | C5: Latvijas Universitātes | D5: 100000 | E5: 70000 | F5: =+E5/D5 -> 0.7 | G5: 13 | H5: -
B6: Finland | C6: Korihait | D6: 345000 | E6: 203500 | F6: =+E6/D6 -> 0.58985507 | G6: 4 | H6: -
B7: Latvia | C7: Liepaja | D7: 400000 | E7: 250000 | F7: =+E7/D7 -> 0.625 | G7: 11 | H7: -
B8: Finland | C8: Bisons Laimaa | D8: 325800 | E8: 255000 | F8: =+E8/D8 -> 0.78268877 | G8: 9 | H8: -
B9: Finland | C9: Tampereen Pyrinto | D9: 402900 | E9: 275900 | F9: =+E9/D9 -> 0.68478531 | G9: 8 | H9: -
B10: Finland | C10: Kouvot | D10: 611800 | E10: 287000 | F10: =+E10/D10 -> 0.46910755 | G10: 11 | H10: -
B11: Finland | C11: Kobrat | D11: 352000 | E11: 305000 | F11: =+E11/D11 -> 0.86647727 | G11: 12 | H11: -
B12: Finland | C12: KTP Basket | D12: 442500 | E12: 307500 | F12: =+E12/D12 -> 0.69491525 | G12: 3 | H12: -
B13: Finland | C13: Tampiolan Honka | D13: 340000 | E13: 313300 | F13: =+E13/D13 -> 0.92147059 | G13: 5 | H13: -
B14: Latvia | C14: Ogre | D14: 550000 | E14: 350000 | F14: =+E14/D14 -> 0.63636364 | G14: 9 | H14: -
B15: Czech Republic | C15: Basket Brno | D15: 587238.02 | E15: 400000 | F15: =+E15/D15 -> 0.68115481 | G15: 3 | H15: Fiba Europe Cup - did not advance from the group to the next round
B16: Latvia | C16: Ventspilis | D16: 650000 | E16: 400000 | F16: =+E16/D16 -> 0.61538462 | G16: 7 | H16: -
... B22: Finland | C22: Kauhajoki | D22: 816000 | E22: 514000 | F22: =+E22/D22 -> 0.62990196 | G22: 2 | H22: -
B23: Finland | C23: BC Nokia | D23: 761500 | E23: 515000 | F23: =+E23/D23 -> 0.67629678 | G23: - | H23: -
B24: Lithuania | C24: Nevėžis | D24: 1000000 | E24: 540000 | F24: =+E24/D24 -> 0.54 | G24: 9 | H24: -
B25: Latvia | C25: Riga Zelli | D25: 950000 | E25: 560000 | F25: =+E25/D25 -> 0.58947368 | G25: 5 | H25: ENBL - Top 8 / quarter-finals
B26: Latvia | C26: Valmiera Glass/ViA | D26: 1100000 | E26: 600000 | F26: =+E26/D26 -> 0.54545455 | G26: 3 | H26: ENBL - Top 16
B27: Poland | C27: Miasto Szkła Krosno | D27: 941620.8 | E27: 600000 | F27: =+E27/D27 -> 0.63719918 | G27: 16 | H27: -
B28: Slovenia | C28: Perspektiva Illirija | D28: 957423 | E28: 600000 | F28: =+E28/D28 -> 0.62668225 | G28: 14 | H28: -
B29: Finland | C29: Helsinki Seagulls | D29: 1142200 | E29: 600800 | F29: =+E29/D29 -> 0.52600245 | G29: 6 | H29: -
B30: Hungary | C30: Alba-Fehervar | D30: 930292.38 | E30: 650000 | F30: =+E30/D30 -> 0.69870507 | G30: 5 | H30: -
B31: Montenegro | C31: Studentski Centar Derby | D31: 1000000 | E31: 650000 | F31: =+E31/D31 -> 0.65 | G31: 15 | H31: -
B32: Serbia | C32: Borac Mozzart | D32: 1000000 | E32: 650000 | F32: =+E32/D32 -> 0.65 | G32: 17 | H32: -
B33: Estonia | C33: Tartu Ulikool | D33: 1200000 | E33: 650000 | F33: =+E33/D33 -> 0.54166667 | G33: 1 | H33: Fiba Europe Cup - did not advance from the group to the next round
B34: Lithuania | C34: Jonava | D34: 1135000 | E34: 666863 | F34: =+E34/D34 -> 0.58754449 | G34: 8 | H34: -
B35: Latvia | C35: Vef Riga | D35: 1500000 | E35: 675000 | F35: =+E35/D35 -> 0.45 | G35: 2 | H35: BCL - did not advance from the group to the next round
... B40: Romania | C40: CS Vâlcea 1924 | D40: 1650000 | E40: 1000000 | F40: =+E40/D40 -> 0.60606061 | G40: 9 | H40: Fiba Europe Cup - did not advance from the group to the next round
B41: Greece | C41: Karditsas | D41: 1500000 | E41: 1000000 | F41: =E41/D41 -> 0.66666667 | G41: 11 | H41: BCL - Top 16
B42: Hungary | C42: Kaposvari | D42: 1726451 | E42: 1100000 | F42: =+E42/D42 -> 0.63714522 | G42: 3 | H42: -
B43: Lithuania | C43: Šiauliai | D43: 2000000 | E43: 1100000 | F43: =+E43/D43 -> 0.55 | G43: 4 | H43: -
B44: Poland | C44: King Wilki Morskie Szczecin | D44: 1765539 | E44: 1100000 | F44: =+E44/D44 -> 0.6230392 | G44: 2 | H44: -
B45: Romania | C45: CS Dinamo Bucharest | D45: 1800000 | E45: 1100000 | F45: =+E45/D45 -> 0.61111111 | G45: 2 | H45: -
B46: Lithuania | C46: Lietkabelis | D46: 2600000 | E46: 1200000 | F46: =+E46/D46 -> 0.46153846 | G46: 5 | H46: Eurocup - regular season 9 place
B47: Poland | C47: Trefl Sopot | D47: 1900000 | E47: 1200000 | F47: =+E47/D47 -> 0.63157895 | G47: 4 | H47: Fiba Europe Cup - Top 16
B48: Serbia | C48: FMP Beograd | D48: 1850000 | E48: 1200000 | F48: =+E48/D48 -> 0.64864865 | G48: 12 | H48: -
B49: Lithuania | C49: Neptūnas | D49: 2800000 | E49: 1220000 | F49: =+E49/D49 -> 0.43571429 | G49: 3 | H49: Eurocup - regular season 8 place
B50: France | C50: Boulazac | D50: 3853000 | E50: 1242000 | F50: =+E50/D50 -> 0.32234622 | G50: 12 | H50: -
B51: Czech Republic | C51: Era Nymburk | D51: 2000000 | E51: 1300000 | F51: =+E51/D51 -> 0.65 | G51: 1 | H51: BCL - Top 8 / quarter-finals
...

Sheet Attendance
B1: Season 25/26
B3: Prancūzijos lyga (Betclic Elite)
B4: Klubas | C4: Vidutinis žiūrovų skaičius | D4: Arena talpina | E4: Užpildymas | F4: Vieta nac. čemp. turnyrinėje lentelėje po reg. sezono
B5: Paris | C5: 6288 | D5: 6750 | E5: =C5/D5 -> 0.93155556 | F5: 1
B6: Strasbourg | C6: 5819 | D6: 6200 | E6: =C6/D6 -> 0.93854839 | F6: 8
B7: Nancy | C7: 5751 | D7: 5850 | E7: =C7/D7 -> 0.98307692 | F7: 10
B8: Asvel | C8: 5287 | D8: 5550 | E8: =C8/D8 -> 0.95261261 | F8: 4
B9: Le Mans | C9: 5228 | D9: 6000 | E9: =C9/D9 -> 0.87133333 | F9: 6
B10: Boulazac | C10: 4922 | D10: 5100 | E10: =C10/D10 -> 0.96509804 | F10: 12
B11: Cholet | C11: 4713 | D11: 4720 | E11: =C11/D11 -> 0.99851695 | F11: 5
B12: Chalon | C12: 4578 | D12: 4620 | E12: =C12/D12 -> 0.99090909 | F12: 9
B13: Limoges | C13: 4397 | D13: 4750 | E13: =C13/D13 -> 0.92568421 | F13: 13
B14: Nanterre | C14: 3614 | D14: 3950 | E14: =C14/D14 -> 0.91493671 | F14: 3
B15: Bourg-en-Bresse | C15: 3492 | D15: 3500 | E15: =C15/D15 -> 0.99771429 | F15: 7
B16: Dijon | C16: 3228 | D16: 3650 | E16: =C16/D16 -> 0.88438356 | F16: 11
... B20: Gravelines | C20: 2090 | D20: 2150 | E20: =C20/D20 -> 0.97209302 | F20: 14
B22: Vidurkis | C22: =average(C5:C20) -> 4236.75
B25: Vokietijos lyga (easyCredit BBL)
B26: Klubas | C26: Vidutinis žiūrovų skaičius | D26: Arena talpina | E26: Užpildymas | F26: Vieta nac. čemp. turnyrinėje lentelėje po reg. sezono | G26: https://easycredit-bbl.de/statistiken/zuschauer
B27: Alba Berlin | C27: 8616 | D27: 13488 / 8780 | E27: =C27/D27 -> #VALUE! | F27: 2
B28: Telekom Baskets Bonn | C28: 6471 | D28: 18500 / 6000 | E28: =C28/D28 -> #VALUE! | F28: 4
B29: FC Bayern | C29: 6452 | D29: 11500 / 6731 | E29: =C29/D29 -> #VALUE! | F29: 1
B30: EWE Baskets Oldenburg | C30: 6256 | D30: 6335 / 3148 | E30: =C30/D30 -> #VALUE! | F30: 11
B31: Ratiopharm Ulm | C31: 5584 | D31: 6000 | E31: =C31/D31 -> 0.93066667 | F31: 6
B32: Gladiators Trier | C32: 5351 | D32: 5400 | E32: =C32/D32 -> 0.99092593 | F32: 8
B33: Bamberg Baskets | C33: 5096 | D33: 5700 | E33: =C33/D33 -> 0.89403509 | F33: 3
B34: MLP Academics Heidelberg | C34: 4610 | D34: 14713 / 4521 | E34: =C34/D34 -> #VALUE! | F34: 18
B35: Niners Chemnitz | C35: 4602 | D35: 5000 | E35: =C35/D35 -> 0.9204 | F35: 12
B36: Frankfurt Skyliners | C36: 4321 | D36: 5002 | E36: =C36/D36 -> 0.86385446 | F36: 15
B37: Lowen Braunschweig | C37: 4212 | D37: 6358 | E37: =C37/D37 -> 0.66247248 | F37: 17
B38: Rostock Seawolves | C38: 4112 | D38: 5000 | E38: =C38/D38 -> 0.8224 | F38: 9
B39: MHP Riesen Ludwigsburg | C39: 3908 | D39: 4000 | E39: =C39/D39 -> 0.977 | F39: 10
B40: Hamburg Towers | C40: 3844 | D40: 12015 / 3400 | E40: =C40/D40 -> #VALUE! | F40: 14
B41: Rasta Vechta | C41: 3129 | D41: 3140 | E41: =C41/D41 -> 0.99649682 | F41: 7
B42: Wurzburg | C42: 3106 | D42: 3140 | E42: =C42/D42 -> 0.98917197 | F42: 5
B43: Science City Jena | C43: 2900 | D43: 3125 | E43: =C43/D43 -> 0.928 | F43: 16
B44: Syntainics MBC | C44: 2788 | D44: 12000 / 3000 | E44: =C44/D44 -> #VALUE! | F44: 13
B46: Vidurkis | C46: =average(C27:C44) -> 4742.1111
B49: Ispanijos lyga (liga Endesa)
B50: Klubas | C50: Vidutinis žiūrovų skaičius | D50: Arena talpina | E50: Užpildymas | F50: Vieta nac. čemp. turnyrinėje lentelėje po reg. sezono
...

Sheet Player Salaries
C2: Dollar to euro conversion rate
C3: 2005 summer | D3: 1 usd 0.81 eur
C4: 2007 summer | D4: 1 usd 0.72 eur
C5: 2008 summer | D5: 1 usd 0.65 eur
C6: 2009 summer | D6: 1 usd 0.7 eur
C7: 2010 summer | D7: 1 usd 0.8 eur
C8: 2011 summer | D8: 1 usd 0.7 eur
C9: 2012 summer | D9: 1 usd 0.8 eur
C10: 2013 summer | D10: 1 usd 0.75 eur
C11: 2014 summer | D11: 1 usd 0.75 eur
C12: 2015 summer | D12: 1 usd 0.9 eur
C13: 2016 summer | D13: 1 usd 0.9 eur
C14: 2017 summer | D14: 1 usd 0.86 eur
... C23: 2026 summer | D23: 1 usd 0.88 eur
B25: Role | C25: Name | D25: Country | E25: Team | F25: Season | G25: Contract value | H25: Contract lenght | I25: Monthly Salary | J25: Source 1 | K25: Source 2 | L25: Source 3
B26: Player | C26: Jonas Mačiulis | D26: Greece | E26: AEK | F26: 19/20 | G26: 220000 | H26: Full season | I26: =G26/10 -> 22000 | J26: https://assets.fiba.basketball/image/upload/v1726052961/Corporate%20Images/HQ%20Departments/Legal/BAT%20Awards/1752-21.pdf
B27: Player | C27: Lior Eliyahu | D27: Israel | E27: Hapoel Jerusalem | F27: 18/19 | G27: 425000 | H27: Full season | I27: =G27/10 -> 42500 | J27: https://www.sport5.co.il/articles.aspx?FolderID=407&docID=293704
B28: Player | C28: Žygimantas Janavičius | D28: Lithuania | E28: Klaipėdos Neptūnas | F28: 20/21 | G28: 60000 | H28: Full season | I28: =G28/10 -> 6000 | J28: https://www.15min.lt/naujiena/prenumerata/ivykiai/top-30-geriausiai-apmokamu-lkl-zaideju-zalgirieciu-dominavimas-ir-svarbios-detales-1226-1370624
B29: Player | C29: Mindaugas Kupšas | D29: Lithuania | E29: Utenos Juventus | F29: 20/21 | G29: 65000 | H29: Full season | I29: =G29/10 -> 6500 | J29: https://www.15min.lt/naujiena/prenumerata/ivykiai/top-30-geriausiai-apmokamu-lkl-zaideju-zalgirieciu-dominavimas-ir-svarbios-detales-1226-1370624
B30: Player | C30: Julius Jucikas | D30: Lithuania | E30: Utenos Juventus | F30: 20/21 | G30: 65000 | H30: Full season | I30: =G30/10 -> 6500 | J30: https://www.15min.lt/naujiena/prenumerata/ivykiai/top-30-geriausiai-apmokamu-lkl-zaideju-zalgirieciu-dominavimas-ir-svarbios-detales-1226-1370624
B31: Player | C31: Paulius Valinskas | D31: Lithuania | E31: Lietkabelis | F31: 20/21 | G31: 65000 | H31: Full season | I31: =G31/10 -> 6500 | J31: https://www.15min.lt/naujiena/prenumerata/ivykiai/top-30-geriausiai-apmokamu-lkl-zaideju-zalgirieciu-dominavimas-ir-svarbios-detales-1226-1370624
B32: Player | C32: Rokas Jokubaitis | D32: Lithuania | E32: Kauno Žalgiris | F32: 20/21 | G32: 70000 | H32: Full season | I32: =G32/10 -> 7000 | J32: https://www.15min.lt/naujiena/prenumerata/ivykiai/top-30-geriausiai-apmokamu-lkl-zaideju-zalgirieciu-dominavimas-ir-svarbios-detales-1226-1370624
B33: Player | C33: Kyle Vinales | D33: Lithuania | E33: Lietkabelis | F33: 20/21 | G33: 70000 | H33: Full season | I33: =G33/10 -> 7000 | J33: https://www.15min.lt/naujiena/prenumerata/ivykiai/top-30-geriausiai-apmokamu-lkl-zaideju-zalgirieciu-dominavimas-ir-svarbios-detales-1226-1370624
B34: Player | C34: Glen Rice Jr. | D34: Lithuania | E34: Utenos Juventus | F34: 20/21 | G34: 70000 | H34: Full season | I34: =G34/10 -> 7000 | J34: https://www.15min.lt/naujiena/prenumerata/ivykiai/top-30-geriausiai-apmokamu-lkl-zaideju-zalgirieciu-dominavimas-ir-svarbios-detales-1226-1370624
B35: Player | C35: Mindaugas Lukauskis | D35: Lithuania | E35: Rytas Vilnius | F35: 14/15 | G35: 80000 | H35: Full season | I35: =G35/10 -> 8000 | J35: https://www.krepsinis.net/naujiena/10-lkl-zaidzianciu-lietuviu-kurie-uzdirba-daugiausiai/248876 | K35: https://www.basketnews.lt/news-83614-kiek-uzdirba-didziuju-lkl-klubu-krepsininkai.html
B36: Player | C36: Artūras Valeika | D36: Lithuania | E36: Rytas Vilnius | F36: 14/15 | G36: 60000 | H36: Full season | I36: =G36/10 -> 6000 | J36: https://www.basketnews.lt/news-83614-kiek-uzdirba-didziuju-lkl-klubu-krepsininkai.html
B37: Player | C37: Marin Marič | D37: Lithuania | E37: Lietkabelis | F37: 20/21 | G37: 70000 | H37: Full season | I37: =G37/10 -> 7000 | J37: https://www.15min.lt/naujiena/prenumerata/ivykiai/top-30-geriausiai-apmokamu-lkl-zaideju-zalgirieciu-dominavimas-ir-svarbios-detales-1226-1370624
B38: Player | C38: Žygimantas Janavičius | D38: Lithuania | E38: Rytas Vilnius | F38: 14/15 | G38: 80000 | H38: Full season | I38: =G38/10 -> 8000 | J38: https://www.basketnews.lt/news-83614-kiek-uzdirba-didziuju-lkl-klubu-krepsininkai.html
B39: Player | C39: Gytis Masiulis | D39: Lithuania | E39: Lietkabelis | F39: 20/21 | G39: 90000 | H39: Full season | I39: =G39/10 -> 9000 | J39: https://www.15min.lt/naujiena/prenumerata/ivykiai/top-30-geriausiai-apmokamu-lkl-zaideju-zalgirieciu-dominavimas-ir-svarbios-detales-1226-1370624
B40: Player | C40: Kostas Sloukas | D40: Greece | E40: Panathinaikos | F40: 24/25 | G40: 2680000 | H40: Full season | I40: =G40/10 -> 268000 | J40: https://www.basketnews.lt/news-215342-atskleistos-grigonio-ir-kitu-pao-zaideju-algos.html | K40: https://www.eurohoops.net/en/trademarks/1747585/panathinaikos-olympiacos-player-contracts-euroleague/
B41: Player | C41: Kendrick Nunn | D41: Greece | E41: Panathinaikos | F41: 24/25 | G41: 2390000 | H41: Full season | I41: =G41/10 -> 239000 | J41: https://www.basketnews.lt/news-215342-atskleistos-grigonio-ir-kitu-pao-zaideju-algos.html | K41: https://www.eurohoops.net/en/trademarks/1747585/panathinaikos-olympiacos-player-contracts-euroleague/
B42: Player | C42: Juancho Hernangomez | D42: Greece | E42: Panathinaikos | F42: 24/25 | G42: 2100000 | H42: Full season | I42: =G42/10 -> 210000 | J42: https://www.basketnews.lt/news-215342-atskleistos-grigonio-ir-kitu-pao-zaideju-algos.html | K42: https://www.eurohoops.net/en/trademarks/1747585/panathinaikos-olympiacos-player-contracts-euroleague/
B43: Player | C43: Lorenzo Brown | D43: Greece | E43: Panathinaikos | F43: 24/25 | G43: 1900000 | H43: Full season | I43: =G43/10 -> 190000 | J43: https://www.basketnews.lt/news-215342-atskleistos-grigonio-ir-kitu-pao-zaideju-algos.html | K43: https://www.eurohoops.net/en/trademarks/1747585/panathinaikos-olympiacos-player-contracts-euroleague/ | L43: https://x.com/hizlihucum/status/1803455514354876516
B44: Player | C44: Mathias Lessort | D44: Greece | E44: Panathinaikos | F44: 24/25 | G44: 1700000 | H44: Full season | I44: =G44/10 -> 170000 | J44: https://www.basketnews.lt/news-215342-atskleistos-grigonio-ir-kitu-pao-zaideju-algos.html | K44: https://www.eurohoops.net/en/trademarks/1747585/panathinaikos-olympiacos-player-contracts-euroleague/
B45: Player | C45: Cedi Osman | D45: Greece | E45: Panathinaikos | F45: 24/25 | G45: 1600000 | H45: 9 months | I45: =G45/9 -> 177777.78 | J45: https://www.basketnews.lt/news-215342-atskleistos-grigonio-ir-kitu-pao-zaideju-algos.html | K45: https://www.eurohoops.net/en/trademarks/1747585/panathinaikos-olympiacos-player-contracts-euroleague/
B46: Player | C46: Marius Grigonis | D46: Greece | E46: Panathinaikos | F46: 24/25 | G46: 1100000 | H46: Full season | I46: =G46/10 -> 110000 | J46: https://www.basketnews.lt/news-215342-atskleistos-grigonio-ir-kitu-pao-zaideju-algos.html | K46: https://www.eurohoops.net/en/trademarks/1747585/panathinaikos-olympiacos-player-contracts-euroleague/
B47: Player | C47: Omer Yurtseven | D47: Greece | E47: Panathinaikos | F47: 24/25 | G47: 1000000 | H47: Full season | I47: =G47/10 -> 100000 | J47: https://www.basketnews.lt/news-215342-atskleistos-grigonio-ir-kitu-pao-zaideju-algos.html | K47: https://www.eurohoops.net/en/trademarks/1747585/panathinaikos-olympiacos-player-contracts-euroleague/
B48: Player | C48: Jerian Grant | D48: Greece | E48: Panathinaikos | F48: 24/25 | G48: 1000000 | H48: Full season | I48: =G48/10 -> 100000 | J48: https://www.basketnews.lt/news-215342-atskleistos-grigonio-ir-kitu-pao-zaideju-algos.html | K48: https://www.eurohoops.net/en/trademarks/1747585/panathinaikos-olympiacos-player-contracts-euroleague/
B49: Player | C49: Ioannis Papapetrou | D49: Greece | E49: Panathinaikos | F49: 24/25 | G49: 800000 | H49: Full season | I49: =G49/10 -> 80000 | J49: https://www.basketnews.lt/news-215342-atskleistos-grigonio-ir-kitu-pao-zaideju-algos.html | K49: https://www.eurohoops.net/en/trademarks/1747585/panathinaikos-olympiacos-player-contracts-euroleague/
B50: Player | C50: Konstantinos Mitoglou | D50: Greece | E50: Panathinaikos | F50: 24/25 | G50: 800000 | H50: Full season | I50: =G50/10 -> 80000 | J50: https://www.basketnews.lt/news-215342-atskleistos-grigonio-ir-kitu-pao-zaideju-algos.html | K50: https://www.eurohoops.net/en/trademarks/1747585/panathinaikos-olympiacos-player-contracts-euroleague/
...

Sheet Notes
K4: zvezda
K5: real
K6: partizan
K7: maccabi
K8: zalgiris
D9: https://www.codesports.com.au/basketball/nbl/nbl-rich-list-the-leagues-highest-paid-player-revealed/news-story/7866be502730868a77169f1f2856db47
D10: https://www.codesports.com.au/basketball/nbl/nbl-bestfive-salaries-revealed-how-one-team-made-mockery-of-1m-pay-gap/news-story/11236aedcbe8c0e7de112b82d144ffe1
D11: https://www.codesports.com.au/basketball/nbl/the-true-cost-of-nbl-success-revealed-in-new-salary-cap-spending-figures/news-story/1c36297db11ed850a8217c70dafb8f92
D13: https://sports.walla.co.il/item/1656259
D14: https://www.globes.co.il/news/article.aspx?did=1000820527
D15: https://www.globes.co.il/news/article.aspx?did=1000483989
D16: https://www.globes.co.il/news/article.aspx?did=1001069020
D17: https://www.globes.co.il/news/article.aspx?did=1000867378
D22: https://www.basketnews.lt/news-132027-mindaugas-kupsas-keliasi-i-jeruzales-hapoel.html?fbclid=IwY2xjawSn9XRleHRuA2FlbQIxMQBicmlkETBRa2FRZjNJbGxOWWRyTHNzc3J0YwZhcHBfaWQQMjIyMDM5MTc4ODIwMDg5MgABHlm5BCQ9jSwT8P3jFbaUb1T0hNZeRWcXnY2RiFZPQk9Syf7avvwq6EYBjFFV_aem_iZGGco9Mo0F0VyMHyS3P-w
D23: https://www.krepsinis.net/naujiena/atskleistos-prancuzijos-lygos-zaideju-ir-treneriu-algos-tarp-kuriu-ir-d-motiejuno/317346
D24: https://www.krepsinis.net/naujiena/o-samhanas-su-zalgiriu-buvo-sudares-1-4-mln-jav-doleriu-vertes-sutarti/238549
D26: https://sportando.basketball/cameron-hunt-unicaja-malaga-joventut/
... D58: https://www.sport5.co.il/articles.aspx?FolderID=274&docID=561038

Sheet Taxes
B6: Germany | C6: 22/23 | D6: Individuals in Germany are taxed between 14 and 42 percent for taxable income ranging from 11,600 and 66,700 euros. The tax rate is 42 percent up for until 277,000 euros and then is 45 percent for more than that. For an unmarried player with no children, a net salary of 60,000 euros needs a gross salary of 133,500 euros, according to the German league. A net salary of 120,000 euros costs a club a gross salary of 244,500 euros. | E6: https://takingthecharge.substack.com/p/follow-the-money-why-germanys-top
B7: Spain | C7: 22/23 | D7: Spain’s tax situation is a bit different than Germany - though the top rates are actually higher depending on region. The usual rate ranges from 45 to 54 percent with Madrid at 45 percent, Barcelona at 52 percent and Valencia at 54 percent. The tax rate in the northern Spanish area Basque Country, however, is only 20-22 percent with the major clubs there being Baskonia and Bilbao. One major difference in Spain is if you are a non-resident, meaning you are in the country for 182 days or fewer. Then you are only taxed at 24 percent. If a player stays in the country a second season, they then fall under the higher rates. But a player can stay in Spain for one season at 24 percent and then leave the country for a season and return and they are once again taxed at 24 percent - but just for that first season back
B8: Greece | C8: 22/23 | D8: The tax rate in Greece is 22 percent, which changed more than 4 years ago after the country’s financial collapse. It had been 40-45 percent up to 100,000 euros and then up to 55 percent for up to 1 million euros. There was a luxury tax for more than that. For example, when Vasilis Spanoulis signed with Olympiacos in 2010 the club paid 5.1 million euros for his 2.4 million euro net salary.
B9: https://x.com/baekpd1983/status/2075466142232326546
